<?xml version="1.0" encoding="utf-8"?>
<!-- This URDF was automatically created by SolidWorks to URDF Exporter! Originally created by Stephen Brawner (brawner@gmail.com) 
     Commit Version: 1.6.0-4-g7f85cfe  Build Version: 1.6.7995.38578
     For more information, please see http://wiki.ros.org/sw_urdf_exporter -->
<robot
  name="New Arm(urdf)">
<link name="worldb"/>
    
    <joint name="world_joint" type="fixed">
      <parent link="worldb"/>
      <child link="base_link"/>
      <origin xyz="0 0 0" rpy="-4.7124 0 0"/>
    </joint>
  <link
    name="base_link">
    <inertial>
      <origin
        xyz="0.15197 0.078447 0.21413"
        rpy="0 0 0" />
      <mass
        value="12.767" />
      <inertia
        ixx="0.076218"
        ixy="0.0052589"
        ixz="0.0011083"
        iyy="0.1036"
        iyz="-0.00048058"
        izz="0.076242" />
    </inertial>
    <visual>
      <origin
        xyz="0 0 0"
        rpy="0 0 0" />
      <geometry>
        <mesh
          filename="../meshes/base_link.STL" />
      </geometry>
      <material
        name="">
        <color
          rgba="0.89804 0.91765 0.92941 1" />
      </material>
    </visual>
    <collision>
      <origin
        xyz="0 0 0"
        rpy="0 0 0" />
      <geometry>
        <mesh
          filename="../meshes/base_link.STL" />
      </geometry>
    </collision>
  </link>
  <link
    name="tt">
    <inertial>
      <origin
        xyz="-1.9736E-05 0.1536 -0.00077976"
        rpy="0 0 0" />
      <mass
        value="0.12993" />
      <inertia
        ixx="0.00032026"
        ixy="6.6005E-08"
        ixz="-4.3915E-07"
        iyy="0.00010911"
        iyz="2.6078E-06"
        izz="0.00030292" />
    </inertial>
    <visual>
      <origin
        xyz="0 0 0"
        rpy="0 0 0" />
      <geometry>
        <mesh
          filename="../meshes/tt.STL" />
      </geometry>
      <material
        name="">
        <color
          rgba="0.79216 0.81961 0.93333 1" />
      </material>
    </visual>
    <collision>
      <origin
        xyz="0 0 0"
        rpy="0 0 0" />
      <geometry>
        <mesh
          filename="../meshes/tt.STL" />
      </geometry>
    </collision>
  </link>
  <joint
    name="tt"
    type="revolute">
    <origin
      xyz="0.151 0.010905 -0.0415"
      rpy="0 0 0" />
    <parent
      link="base_link" />
    <child
      link="tt" />
    <axis
      xyz="0 -1 0" />
    <limit
      lower="-3.14"
      upper="3.14"
      effort="0"
      velocity="0" />
  </joint>
  <link
    name="link1">
    <inertial>
      <origin
        xyz="-0.034 0.18564 0.22733"
        rpy="0 0 0" />
      <mass
        value="0.22944" />
      <inertia
        ixx="0.00518"
        ixy="-1.1796E-18"
        ixz="-1.7212E-18"
        iyy="0.0030763"
        iyz="-0.0024434"
        izz="0.0021215" />
    </inertial>
    <visual>
      <origin
        xyz="0 0 0"
        rpy="0 0 0" />
      <geometry>
        <mesh
          filename="../meshes/link1.STL" />
      </geometry>
      <material
        name="">
        <color
          rgba="0.79216 0.81961 0.93333 1" />
      </material>
    </visual>
    <collision>
      <origin
        xyz="0 0 0"
        rpy="0 0 0" />
      <geometry>
        <mesh
          filename="../meshes/link1.STL" />
      </geometry>
    </collision>
  </link>
  <joint
    name="link1"
    type="revolute">
    <origin
      xyz="0.033255 0.2121 -0.029851"
      rpy="0 0.025305 0" />
    <parent
      link="tt" />
    <child
      link="link1" />
    <axis
      xyz="-1 0 0" />
    <limit
      lower="-3.14"
      upper="3.14"
      effort="0"
      velocity="0" />
  </joint>
  <link
    name="link2">
    <inertial>
      <origin
        xyz="0.028 0.15109 -0.14585"
        rpy="0 0 0" />
      <mass
        value="0.20937" />
      <inertia
        ixx="0.0035916"
        ixy="-6.1436E-19"
        ixz="3.6931E-19"
        iyy="0.00179"
        iyz="0.0017084"
        izz="0.0018049" />
    </inertial>
    <visual>
      <origin
        xyz="0 0 0"
        rpy="0 0 0" />
      <geometry>
        <mesh
          filename="../meshes/link2.STL" />
      </geometry>
      <material
        name="">
        <color
          rgba="0.79216 0.81961 0.93333 1" />
      </material>
    </visual>
    <collision>
      <origin
        xyz="0 0 0"
        rpy="0 0 0" />
      <geometry>
        <mesh
          filename="../meshes/link2.STL" />
      </geometry>
    </collision>
  </link>
  <joint
    name="link2"
    type="revolute">
    <origin
      xyz="-0.062 0.30929 0.39286"
      rpy="0 0 0" />
    <parent
      link="link1" />
    <child
      link="link2" />
    <axis
      xyz="1 0 0" />
    <limit
      lower="-3.14"
      upper="3.14"
      effort="0"
      velocity="0" />
  </joint>
  <link
    name="link3">
    <inertial>
      <origin
        xyz="-0.022442 -0.045811 0.25032"
        rpy="0 0 0" />
      <mass
        value="0.43466" />
      <inertia
        ixx="0.0015194"
        ixy="7.8224E-07"
        ixz="1.077E-07"
        iyy="0.0014144"
        iyz="0.00014626"
        izz="0.00037064" />
    </inertial>
    <visual>
      <origin
        xyz="0 0 0"
        rpy="0 0 0" />
      <geometry>
        <mesh
          filename="../meshes/link3.STL" />
      </geometry>
      <material
        name="">
        <color
          rgba="0.79216 0.81961 0.93333 1" />
      </material>
    </visual>
    <collision>
      <origin
        xyz="0 0 0"
        rpy="0 0 0" />
      <geometry>
        <mesh
          filename="../meshes/link3.STL" />
      </geometry>
    </collision>
  </link>
  <joint
    name="link3"
    type="revolute">
    <origin
      xyz="0 0.29017 -0.27532"
      rpy="3.1416 0 3.1416" />
    <parent
      link="link2" />
    <child
      link="link3" />
    <axis
      xyz="-1 0 0" />
    <limit
      lower="-3.14"
      upper="3.14"
      effort="0"
      velocity="0" />
  </joint>
  <link
    name="ypr pitch">
    <inertial>
      <origin
        xyz="0.025873 -5.1941E-05 -1.737E-05"
        rpy="0 0 0" />
      <mass
        value="0.19925" />
      <inertia
        ixx="0.00015622"
        ixy="-4.1005E-11"
        ixz="-1.8839E-11"
        iyy="0.00012636"
        iyz="-5.3401E-06"
        izz="0.00014056" />
    </inertial>
    <visual>
      <origin
        xyz="0 0 0"
        rpy="0 0 0" />
      <geometry>
        <mesh
          filename="../meshes/ypr pitch.STL" />
      </geometry>
      <material
        name="">
        <color
          rgba="0.79216 0.81961 0.93333 1" />
      </material>
    </visual>
    <collision>
      <origin
        xyz="0 0 0"
        rpy="0 0 0" />
      <geometry>
        <mesh
          filename="../meshes/ypr pitch.STL" />
      </geometry>
    </collision>
  </link>
  <joint
    name="ypr pitch"
    type="revolute">
    <origin
      xyz="-0.028 -0.077678 0.40923"
      rpy="-1.5708 -0.13663 1.5708" />
    <parent
      link="link3" />
    <child
      link="ypr pitch" />
    <axis
      xyz="-1 0 0" />
    <limit
      lower="-3.14"
      upper="3.14"
      effort="0"
      velocity="0" />
  </joint>
  <link
    name="ypr roll">
    <inertial>
      <origin
        xyz="-0.0029709 -0.010436 -0.089727"
        rpy="0 0 0" />
      <mass
        value="0.59855" />
      <inertia
        ixx="0.001022"
        ixy="-1.4319E-05"
        ixz="2.3671E-06"
        iyy="0.00058057"
        iyz="5.8323E-05"
        izz="0.00070733" />
    </inertial>
    <visual>
      <origin
        xyz="0 0 0"
        rpy="0 0 0" />
      <geometry>
        <mesh
          filename="../meshes/ypr roll.STL" />
      </geometry>
      <material
        name="">
        <color
          rgba="0.79216 0.81961 0.93333 1" />
      </material>
    </visual>
    <collision>
      <origin
        xyz="0 0 0"
        rpy="0 0 0" />
      <geometry>
        <mesh
          filename="../meshes/ypr roll.STL" />
      </geometry>
    </collision>
  </link>
  <joint
    name="ypr roll"
    type="revolute">
    <origin
      xyz="0.025873 -0.021203 -0.0070861"
      rpy="0.010968 -1.2482 -1.5824" />
    <parent
      link="ypr pitch" />
    <child
      link="ypr roll" />
    <axis
      xyz="0 0 -1" />
    <limit
      lower="-3.14"
      upper="3.14"
      effort="0"
      velocity="0" />
  </joint>
  <link
    name="claw">
    <inertial>
      <origin
        xyz="-0.014064 0.12149 0.038797"
        rpy="0 0 0" />
      <mass
        value="0.086144" />
      <inertia
        ixx="0.00011348"
        ixy="7.6268E-07"
        ixz="3.0969E-05"
        iyy="0.00012088"
        iyz="-2.104E-06"
        izz="3.927E-05" />
    </inertial>
    <visual>
      <origin
        xyz="0 0 0"
        rpy="0 0 0" />
      <geometry>
        <mesh
          filename="../meshes/claw.STL" />
      </geometry>
      <material
        name="">
        <color
          rgba="0.79216 0.81961 0.93333 1" />
      </material>
    </visual>
    <collision>
      <origin
        xyz="0 0 0"
        rpy="0 0 0" />
      <geometry>
        <mesh
          filename="../meshes/claw.STL" />
      </geometry>
    </collision>
  </link>
  <joint
    name="claw"
    type="fixed">
    <origin
      xyz="-0.00027829 0.08223 -0.11311"
      rpy="3.1416 -0.34776 -0.032181" />
    <parent
      link="ypr roll" />
    <child
      link="claw" />
    <axis
      xyz="0 -1 0" />
    <limit
      lower="-3.14"
      upper="3.14"
      effort="0"
      velocity="0" />
  </joint>
</robot>