<?xml version="1.0" encoding="utf-8"?>
<!-- This URDF was automatically created by SolidWorks to URDF Exporter! Originally created by Stephen Brawner (brawner@gmail.com) 
     Commit Version: 1.6.0-4-g7f85cfe  Build Version: 1.6.7995.38578
     For more information, please see http://wiki.ros.org/sw_urdf_exporter -->
<robot
  name="New Arm(urdf)2">
<link name="worldb"/>

    <joint name="world_joint" type="fixed">
      <parent link="worldb"/>
      <child link="base_link"/>
      <origin xyz="0 0 0" rpy="-1.518 0 0"/>
     
    </joint>

  <link
    name="base_link">
    <inertial>
      <origin
        xyz="0.15197 0.078447 0.21413"
        rpy="0 0 0" />
      <mass
        value="12.767" />
      <inertia
        ixx="0.076218"
        ixy="0.0052589"
        ixz="0.0011083"
        iyy="0.1036"
        iyz="-0.00048058"
        izz="0.076242" />
    </inertial>
    <visual>
      <origin
        xyz="0 0 0"
        rpy="0 0 0" />
      <geometry>
        <mesh
          filename="../meshes/base_link.STL" />
      </geometry>
      <material
        name="">
        <color
          rgba="0.89804 0.91765 0.92941 1" />
      </material>
    </visual>
    <collision>
      <origin
        xyz="0 0 0"
        rpy="0 0 0" />
      <geometry>
        <mesh
          filename="../meshes/base_link.STL" />
      </geometry>
    </collision>
  </link>
  <link
    name="tt">
    <inertial>
      <origin
        xyz="-1.9736E-05 0.1536 -0.00077976"
        rpy="0 0 0" />
      <mass
        value="0.12993" />
      <inertia
        ixx="0.00032026"
        ixy="6.6005E-08"
        ixz="-4.3915E-07"
        iyy="0.00010911"
        iyz="2.6078E-06"
        izz="0.00030292" />
    </inertial>
    <visual>
      <origin
        xyz="0 0 0"
        rpy="0 0 0" />
      <geometry>
        <mesh
          filename="../meshes/tt.STL" />
      </geometry>
      <material
        name="">
        <color
          rgba="0.79216 0.81961 0.93333 1" />
      </material>
    </visual>
    <collision>
      <origin
        xyz="0 0 0"
        rpy="0 0 0" />
      <geometry>
        <mesh
          filename="../meshes/tt.STL" />
      </geometry>
    </collision>
  </link>
  <joint
    name="tt"
    type="revolute">
    <origin
      xyz="1.31 -0.0548 -0.212"
      rpy="-3.1416 1.5708 0" />
    <parent
      link="base_link" />
    <child
      link="tt" />
    <axis
      xyz="0 -1 0" />
    <limit
      lower="-6.28"
      upper="6.28"
      effort="0"
      velocity="0" />
  </joint>
  <link
    name="link1">
    <inertial>
      <origin
        xyz="-0.0340000000000024 0.185638009583591 0.227327343793081"
        rpy="0 0 0" />
      <mass
        value="0.229444432647079" />
      <inertia
        ixx="0.00517995575355324"
        ixy="-1.13890042344786E-18"
        ixz="-1.69067776271958E-18"
        iyy="0.00307630079481334"
        iyz="-0.00244340869793796"
        izz="0.00212147001056029" />
    </inertial>
    <visual>
      <origin
        xyz="0 0 0"
        rpy="0 0 0" />
      <geometry>
        <mesh
          filename="../meshes/link1.STL" />
      </geometry>
      <material
        name="">
        <color
          rgba="0.792156862745098 0.819607843137255 0.933333333333333 1" />
      </material>
    </visual>
    <collision>
      <origin
        xyz="0 0 0"
        rpy="0 0 0" />
      <geometry>
        <mesh
          filename="../meshes/link1.STL" />
      </geometry>
    </collision>
  </link>
  <joint
    name="link1"
    type="revolute">
    <origin
      xyz="0.033255 0.2121 -0.029851"
      rpy="0 0.025305 0" />
    <parent
      link="tt" />
    <child
      link="link1" />
    <axis
      xyz="-1 0 0" />
    <limit
      lower="-3.14"
      upper="3.14"
      effort="0"
      velocity="0" />
  </joint>
  <link
    name="link2">
    <inertial>
      <origin
        xyz="0.028000000000014 0.151085436627092 -0.145850255195239"
        rpy="0 0 0" />
      <mass
        value="0.209369199831917" />
      <inertia
        ixx="0.00359156187538785"
        ixy="-6.14364096535471E-19"
        ixz="3.62530101424841E-19"
        iyy="0.0017899965671378"
        iyz="0.00170843639396794"
        izz="0.00180491914611627" />
    </inertial>
    <visual>
      <origin
        xyz="0 0 0"
        rpy="0 0 0" />
      <geometry>
        <mesh
          filename="../meshes/link2.STL" />
      </geometry>
      <material
        name="">
        <color
          rgba="0.792156862745098 0.819607843137255 0.933333333333333 1" />
      </material>
    </visual>
    <collision>
      <origin
        xyz="0 0 0"
        rpy="0 0 0" />
      <geometry>
        <mesh
          filename="../meshes/link2.STL" />
      </geometry>
    </collision>
  </link>
  <joint
    name="link2"
    type="revolute">
    <origin
      xyz="-0.062 0.30929 0.39286"
      rpy="0 0 0" />
    <parent
      link="link1" />
    <child
      link="link2" />
    <axis
      xyz="1 0 0" />
    <limit
      lower="-3.14"
      upper="3.14"
      effort="0"
      velocity="0" />
  </joint>
  <link
    name="link3">
    <inertial>
      <origin
        xyz="-0.0224419253502595 -0.0458110944968314 0.250321755506889"
        rpy="0 0 0" />
      <mass
        value="0.434663057886458" />
      <inertia
        ixx="0.00151940083284689"
        ixy="7.82235915987114E-07"
        ixz="1.07698692467981E-07"
        iyy="0.00141443101254521"
        iyz="0.000146264122895242"
        izz="0.000370638003884554" />
    </inertial>
    <visual>
      <origin
        xyz="0 0 0"
        rpy="0 0 0" />
      <geometry>
        <mesh
          filename="../meshes/link3.STL" />
      </geometry>
      <material
        name="">
        <color
          rgba="0.792156862745098 0.819607843137255 0.933333333333333 1" />
      </material>
    </visual>
    <collision>
      <origin
        xyz="0 0 0"
        rpy="0 0 0" />
      <geometry>
        <mesh
          filename="../meshes/link3.STL" />
      </geometry>
    </collision>
  </link>
  <joint
    name="link3"
    type="revolute">
    <origin
      xyz="0 0.29017 -0.27532"
      rpy="3.1416 0 3.1416" />
    <parent
      link="link2" />
    <child
      link="link3" />
    <axis
      xyz="-1 0 0" />
    <limit
      lower="-3.14"
      upper="3.14"
      effort="0"
      velocity="0" />
  </joint>
  <link
    name="ypr pitch">
    <inertial>
      <origin
        xyz="0.0258725407179815 -5.19410787384045E-05 -1.73703121094659E-05"
        rpy="0 0 0" />
      <mass
        value="0.199246612726693" />
      <inertia
        ixx="0.000156216651475295"
        ixy="-4.10052725417298E-11"
        ixz="-1.88388917346243E-11"
        iyy="0.000126364961370385"
        iyz="-5.34006523912841E-06"
        izz="0.000140559243483286" />
    </inertial>
    <visual>
      <origin
        xyz="0 0 0"
        rpy="0 0 0" />
      <geometry>
        <mesh
          filename="../meshes/ypr pitch.STL" />
      </geometry>
      <material
        name="">
        <color
          rgba="0.792156862745098 0.819607843137255 0.933333333333333 1" />
      </material>
    </visual>
    <collision>
      <origin
        xyz="0 0 0"
        rpy="0 0 0" />
      <geometry>
        <mesh
          filename="../meshes/ypr pitch.STL" />
      </geometry>
    </collision>
  </link>
  <joint
    name="ypr pitch"
    type="revolute">
    <origin
      xyz="-0.028 -0.077678 0.40923"
      rpy="-1.5708 -0.13663 1.5708" />
    <parent
      link="link3" />
    <child
      link="ypr pitch" />
    <axis
      xyz="-1 0 0" />
    <limit
      lower="-3.14"
      upper="3.14"
      effort="0"
      velocity="0" />
  </joint>
  <link
    name="ypr roll">
    <inertial>
      <origin
        xyz="-0.00297090446320836 -0.0104358339225067 -0.0897272059511462"
        rpy="0 0 0" />
      <mass
        value="0.598549884728632" />
      <inertia
        ixx="0.00102198673239933"
        ixy="-1.43192054707853E-05"
        ixz="2.36714459386942E-06"
        iyy="0.000580572054629292"
        iyz="5.83228149987117E-05"
        izz="0.000707333999702111" />
    </inertial>
    <visual>
      <origin
        xyz="0 0 0"
        rpy="0 0 0" />
      <geometry>
        <mesh
          filename="../meshes/ypr roll.STL" />
      </geometry>
      <material
        name="">
        <color
          rgba="0.792156862745098 0.819607843137255 0.933333333333333 1" />
      </material>
    </visual>
    <collision>
      <origin
        xyz="0 0 0"
        rpy="0 0 0" />
      <geometry>
        <mesh
          filename="../meshes/ypr roll.STL" />
      </geometry>
    </collision>
  </link>
  <joint
    name="ypr roll"
    type="revolute">
    <origin
      xyz="0.025873 -0.021203 -0.0070861"
      rpy="0.010968 -1.2482 -1.5824" />
    <parent
      link="ypr pitch" />
    <child
      link="ypr roll" />
    <axis
      xyz="0 0 -1" />
    <limit
      lower="-3.14"
      upper="3.14"
      effort="0"
      velocity="0" />
  </joint>
  <link
    name="claw">
    <inertial>
      <origin
        xyz="-0.0140636335800565 0.121493659274111 0.0387971752593232"
        rpy="0 0 0" />
      <mass
        value="0.0861437294327855" />
      <inertia
        ixx="0.000113478077427995"
        ixy="7.62682337863518E-07"
        ixz="3.09691019174081E-05"
        iyy="0.000120875433111426"
        iyz="-2.10400250837131E-06"
        izz="3.92700179471421E-05" />
    </inertial>
    <visual>
      <origin
        xyz="0 0 0"
        rpy="0 0 0" />
      <geometry>
        <mesh
          filename="../meshes/claw.STL" />
      </geometry>
      <material
        name="">
        <color
          rgba="0.792156862745098 0.819607843137255 0.933333333333333 1" />
      </material>
    </visual>
    <collision>
      <origin
        xyz="0 0 0"
        rpy="0 0 0" />
      <geometry>
        <mesh
          filename="../meshes/claw.STL" />
      </geometry>
    </collision>
  </link>
  <joint
    name="claw"
    type="fixed">
    <origin
      xyz="-0.00027829 0.08223 -0.11311"
      rpy="3.1416 -0.34776 -0.032181" />
    <parent
      link="ypr roll" />
    <child
      link="claw" />
    <axis
      xyz="0 -1 0" />
    <limit
      lower="-3.14"
      upper="3.14"
      effort="0"
      velocity="0" />
  </joint>
</robot>