<?xml version="1.0" encoding="utf-8"?>
<!-- This URDF was automatically created by SolidWorks to URDF Exporter! Originally created by Stephen Brawner (brawner@gmail.com) 
     Commit Version: 1.6.0-4-g7f85cfe  Build Version: 1.6.7995.38578
     For more information, please see http://wiki.ros.org/sw_urdf_exporter -->
<robot
  name="(3)">
 <link name="worldb"/>
    <joint name="world_joint" type="fixed">
      <parent link="worldb"/>
      <child link="base_link"/>
      <origin xyz="0 0 0" rpy="-1.5708 0 0"/>
    </joint>
  <link
    name="base_link">
    <inertial>
      <origin
        xyz="1.09461925457827 -0.124858087365365 -0.201953049950335"
        rpy="0 0 0" />
      <mass
        value="4.02995163253206" />
      <inertia
        ixx="0.0142526010590084"
        ixy="0.0002672269741825"
        ixz="-0.000921986919945574"
        iyy="0.0120910989509573"
        iyz="0.00166810244583697"
        izz="0.0130919906841085" />
    </inertial>
    <visual>
      <origin
        xyz="0 0 0"
        rpy="0 0 0" />
      <geometry>
        <mesh
          filename="../meshes/base_link.STL" />
      </geometry>
      <material
        name="">
        <color
          rgba="0.792156862745098 0.819607843137255 0.933333333333333 1" />
      </material>
    </visual>
    <collision>
      <origin
        xyz="0 0 0"
        rpy="0 0 0" />
      <geometry>
        <mesh
          filename="../meshes/base_link.STL" />
      </geometry>
    </collision>
  </link>
  <link
    name="turntable">
    <inertial>
      <origin
        xyz="0.105763980678447 -0.000891891988765936 -0.0260116131683339"
        rpy="0 0 0" />
      <mass
        value="2.52870378509003" />
      <inertia
        ixx="0.00641134887101375"
        ixy="0.000853146367351283"
        ixz="-9.61006870504374E-06"
        iyy="0.00486617833905661"
        iyz="2.16935043543991E-05"
        izz="0.00929271252291498" />
    </inertial>
    <visual>
      <origin
        xyz="0 0 0"
        rpy="0 0 0" />
      <geometry>
        <mesh
          filename="../meshes/turntable.STL" />
      </geometry>
      <material
        name="">
        <color
          rgba="0.650980392156863 0.619607843137255 0.588235294117647 1" />
      </material>
    </visual>
    <collision>
      <origin
        xyz="0 0 0"
        rpy="0 0 0" />
      <geometry>
        <mesh
          filename="../meshes/turntable.STL" />
      </geometry>
    </collision>
  </link>
  <joint
    name="turntable_joint"
    type="revolute">
    <origin
      xyz="1.35 -0.216 -0.31116"
      rpy="1.5708 -1.1533 3.1416" />
    <parent
      link="base_link" />
    <child
      link="turntable" />
    <axis
      xyz="0 0 -1" />
    <limit
      lower="0"
      upper="0"
      effort="0"
      velocity="0" />
  </joint>
  <link
    name="worm_pitch">
    <inertial>
      <origin
        xyz="-0.00975815373258329 -0.119432998209141 0.138678111763514"
        rpy="0 0 0" />
      <mass
        value="3.22088245146173" />
      <inertia
        ixx="0.0280751971325729"
        ixy="-3.59522261295735E-08"
        ixz="-5.70039309070435E-07"
        iyy="0.0158829956773457"
        iyz="0.0120530236922504"
        izz="0.0134222737428643" />
    </inertial>
    <visual>
      <origin
        xyz="0 0 0"
        rpy="0 0 0" />
      <geometry>
        <mesh
          filename="../meshes/worm_pitch.STL" />
      </geometry>
      <material
        name="">
        <color
          rgba="0.792156862745098 0.819607843137255 0.933333333333333 1" />
      </material>
    </visual>
    <collision>
      <origin
        xyz="0 0 0"
        rpy="0 0 0" />
      <geometry>
        <mesh
          filename="../meshes/worm_pitch.STL" />
      </geometry>
    </collision>
  </link>
  <joint
    name="pitch1_joint"
    type="revolute">
    <origin
      xyz="0.073516 0.077746 -0.15172"
      rpy="1.5708 0 0.41747" />
    <parent
      link="turntable" />
    <child
      link="worm_pitch" />
    <axis
      xyz="-1 0 0" />
    <limit
      lower="0"
      upper="0"
      effort="0"
      velocity="0" />
  </joint>
  <link
    name="pulley">
    <inertial>
      <origin
        xyz="-0.0673425666244651 -0.0631791995553334 -0.0419109788002336"
        rpy="0 0 0" />
      <mass
        value="1.78809248147294" />
      <inertia
        ixx="0.00213333923198405"
        ixy="-0.000867369411845706"
        ixz="1.95378069418683E-06"
        iyy="0.0022216968306464"
        iyz="-2.21823723312907E-06"
        izz="0.00323857402349486" />
    </inertial>
    <visual>
      <origin
        xyz="0 0 0"
        rpy="0 0 0" />
      <geometry>
        <mesh
          filename="../meshes/pulley.STL" />
      </geometry>
      <material
        name="">
        <color
          rgba="0.898039215686275 0.917647058823529 0.929411764705882 1" />
      </material>
    </visual>
    <collision>
      <origin
        xyz="0 0 0"
        rpy="0 0 0" />
      <geometry>
        <mesh
          filename="../meshes/pulley.STL" />
      </geometry>
    </collision>
  </link>
  <joint
    name="pitch2_joint"
    type="revolute">
    <origin
      xyz="-0.06 -0.28998 0.3107"
      rpy="1.5708 -1.3747 -1.5708" />
    <parent
      link="worm_pitch" />
    <child
      link="pulley" />
    <axis
      xyz="0 0 -1" />
    <limit
      lower="0"
      upper="0"
      effort="0"
      velocity="0" />
  </joint>
  <link
    name="pitch">
    <inertial>
      <origin
        xyz="0.0621093053330855 0.134911342290007 0.00321851094411874"
        rpy="0 0 0" />
      <mass
        value="0.925309424196917" />
      <inertia
        ixx="0.000905421686910921"
        ixy="5.34409864789575E-05"
        ixz="-0.000133446110425349"
        iyy="0.00084039225667281"
        iyz="1.72313152724389E-05"
        izz="0.00123723911318562" />
    </inertial>
    <visual>
      <origin
        xyz="0 0 0"
        rpy="0 0 0" />
      <geometry>
        <mesh
          filename="../meshes/pitch.STL" />
      </geometry>
      <material
        name="">
        <color
          rgba="0.792156862745098 0.819607843137255 0.933333333333333 1" />
      </material>
    </visual>
    <collision>
      <origin
        xyz="0 0 0"
        rpy="0 0 0" />
      <geometry>
        <mesh
          filename="../meshes/pitch.STL" />
      </geometry>
    </collision>
  </link>
  <joint
    name="ypr_pitch_joint"
    type="revolute">
    <origin
      xyz="-0.19051 -0.17768 -0.112"
      rpy="0.90468 -1.5708 0" />
    <parent
      link="pulley" />
    <child
      link="pitch" />
    <axis
      xyz="-1 0 0" />
    <limit
      lower="0"
      upper="0"
      effort="0"
      velocity="0" />
  </joint>
  <link
    name="roll">
    <inertial>
      <origin
        xyz="8.14509761782323E-05 -0.000186184135913703 -0.061867701985606"
        rpy="0 0 0" />
      <mass
        value="0.687630751243602" />
      <inertia
        ixx="0.000820286563080187"
        ixy="0.000210332552441998"
        ixz="-4.09274565567264E-05"
        iyy="0.00082218290708419"
        iyz="4.16297521821321E-05"
        izz="0.000716087275938447" />
    </inertial>
    <visual>
      <origin
        xyz="0 0 0"
        rpy="0 0 0" />
      <geometry>
        <mesh
          filename="../meshes/roll.STL" />
      </geometry>
      <material
        name="">
        <color
          rgba="0.792156862745098 0.819607843137255 0.933333333333333 1" />
      </material>
    </visual>
    <collision>
      <origin
        xyz="0 0 0"
        rpy="0 0 0" />
      <geometry>
        <mesh
          filename="../meshes/roll.STL" />
      </geometry>
    </collision>
  </link>
  <joint
    name="roll"
    type="continuous">
    <origin
      xyz="0.05225 0.069756 0"
      rpy="1.5708 -1.1062 0" />
    <parent
      link="pitch" />
    <child
      link="roll" />
    <axis
      xyz="0 0 -1" />
    <limit
      lower="0"
      upper="0"
      effort="0"
      velocity="0" />
  </joint>
  <link
    name="grip">
    <inertial>
      <origin
        xyz="-0.0264212696817929 6.10622663543836E-15 0.0519403659924387"
        rpy="0 0 0" />
      <mass
        value="0.134543517946272" />
      <inertia
        ixx="5.22930570804675E-05"
        ixy="1.77707512333952E-18"
        ixz="-2.24360153272602E-06"
        iyy="0.000148952960809367"
        iyz="3.21872519956634E-20"
        izz="0.000126256855074672" />
    </inertial>
    <visual>
      <origin
        xyz="0 0 0"
        rpy="0 0 0" />
      <geometry>
        <mesh
          filename="../meshes/grip.STL" />
      </geometry>
      <material
        name="">
        <color
          rgba="0.792156862745098 0.819607843137255 0.933333333333333 1" />
      </material>
    </visual>
    <collision>
      <origin
        xyz="0 0 0"
        rpy="0 0 0" />
      <geometry>
        <mesh
          filename="../meshes/grip.STL" />
      </geometry>
    </collision>
  </link>
  <joint
    name="grip"
    type="fixed">
    <origin
      xyz="0.086479 -0.086479 -0.11021"
      rpy="2.3562 -1.5708 0" />
    <parent
      link="roll" />
    <child
      link="grip" />
    <axis
      xyz="0 0 0" />
    <limit
      lower="0"
      upper="0"
      effort="0"
      velocity="0" />
  </joint>
</robot>