<?xml version="1.0" encoding="utf-8"?>
<!-- This URDF was automatically created by SolidWorks to URDF Exporter! Originally created by Stephen Brawner (brawner@gmail.com) 
     Commit Version: 1.6.0-4-g7f85cfe  Build Version: 1.6.7995.38578
     For more information, please see http://wiki.ros.org/sw_urdf_exporter -->
<robot
  name="ARM urdf">
<link name="worldb"/>
    
    <joint name="world_joint" type="fixed">
      <parent link="worldb"/>
      <child link="base_link"/>
      <origin xyz="0 0 0" rpy="-1.5708 0 0"/>
    </joint>

  <link
    name="base_link">
    <inertial>
      <origin
        xyz="1.1158 -0.10773 -0.23061"
        rpy="0 0 0" />
      <mass
        value="4.0876" />
      <inertia
        ixx="0.01519"
        ixy="0.00029846"
        ixz="-0.00058927"
        iyy="0.011351"
        iyz="0.0016839"
        izz="0.013474" />
    </inertial>
    <visual>
      <origin
        xyz="0 0 0"
        rpy="0 0 0" />
      <geometry>
        <mesh
          filename="../meshes/base_link.STL" />
      </geometry>
      <material
        name="">
        <color
          rgba="0.79216 0.81961 0.93333 1" />
      </material>
    </visual>
    <collision>
      <origin
        xyz="0 0 0"
        rpy="0 0 0" />
      <geometry>
        <mesh
          filename="../meshes/base_link.STL" />
      </geometry>
    </collision>
  </link>
  <link
    name="turntable">
    <inertial>
      <origin
        xyz="-0.0022543 -0.0091992 0.00092136"
        rpy="0 0 0" />
      <mass
        value="2.5424" />
      <inertia
        ixx="0.0059966"
        ixy="1.3976E-05"
        ixz="-0.0010953"
        iyy="0.009303"
        iyz="1.9175E-05"
        izz="0.0052907" />
    </inertial>
    <visual>
      <origin
        xyz="0 0 0"
        rpy="0 0 0" />
      <geometry>
        <mesh
          filename="../meshes/turntable.STL" />
      </geometry>
      <material
        name="">
        <color
          rgba="0.79216 0.81961 0.93333 1" />
      </material>
    </visual>
    <collision>
      <origin
        xyz="0 0 0"
        rpy="0 0 0" />
      <geometry>
        <mesh
          filename="../meshes/turntable.STL" />
      </geometry>
    </collision>
  </link>
  <joint
    name="turntable"
    type="revolute">
    <origin
      xyz="1.3062 -0.232 -0.21244"
      rpy="0 0.94126 0" />
    <parent
      link="base_link" />
    <child
      link="turntable" />
    <axis
      xyz="0 -1 0" />
    <limit
      lower="-6.28"
      upper="6.28"
      effort="0"
      velocity="0" />
  </joint>
  <link
    name="link1">
    <inertial>
      <origin
        xyz="-0.0017673 -0.10544 0.12039"
        rpy="0 0 0" />
      <mass
        value="2.6849" />
      <inertia
        ixx="0.027624"
        ixy="-3.6535E-08"
        ixz="-5.7059E-07"
        iyy="0.015039"
        iyz="0.012093"
        izz="0.013381" />
    </inertial>
    <visual>
      <origin
        xyz="0 0 0"
        rpy="0 0 0" />
      <geometry>
        <mesh
          filename="../meshes/link1.STL" />
      </geometry>
      <material
        name="">
        <color
          rgba="0.79216 0.81961 0.93333 1" />
      </material>
    </visual>
    <collision>
      <origin
        xyz="0 0 0"
        rpy="0 0 0" />
      <geometry>
        <mesh
          filename="../meshes/link1.STL" />
      </geometry>
    </collision>
  </link>
  <joint
    name="pitch1"
    type="revolute">
    <origin
      xyz="0.050075 -0.13572 0.068746"
      rpy="3.1416 -0.62954 3.1416" />
    <parent
      link="turntable" />
    <child
      link="link1" />
    <axis
      xyz="-1 0 0" />
    <limit
      lower="-3.14"
      upper="3.14"
      effort="0"
      velocity="0" />
  </joint>
  <link
    name="link2">
    <inertial>
      <origin
        xyz="-0.065297 -0.06134 -0.062592"
        rpy="0 0 0" />
      <mass
        value="1.7567" />
      <inertia
        ixx="0.0021053"
        ixy="-0.00084408"
        ixz="1.9537E-06"
        iyy="0.0021881"
        iyz="-2.2194E-06"
        izz="0.0031785" />
    </inertial>
    <visual>
      <origin
        xyz="0 0 0"
        rpy="0 0 0" />
      <geometry>
        <mesh
          filename="../meshes/link2.STL" />
      </geometry>
      <material
        name="">
        <color
          rgba="0.79216 0.81961 0.93333 1" />
      </material>
    </visual>
    <collision>
      <origin
        xyz="0 0 0"
        rpy="0 0 0" />
      <geometry>
        <mesh
          filename="../meshes/link2.STL" />
      </geometry>
    </collision>
  </link>
  <joint
    name="pitch2"
    type="revolute">
    <origin
      xyz="-0.081 -0.29511 0.30583"
      rpy="1.5708 -1.2551 -1.5708" />
    <parent
      link="link1" />
    <child
      link="link2" />
    <axis
      xyz="0 0 -1" />
    <limit
      lower="-3.14"
      upper="3.14"
      effort="0"
      velocity="0" />
  </joint>
  <link
    name="diff1">
    <inertial>
      <origin
        xyz="0.010938 0.0095726 -0.026521"
        rpy="0 0 0" />
      <mass
        value="0.33528" />
      <inertia
        ixx="0.00016168"
        ixy="-3.549E-06"
        ixz="-6.267E-09"
        iyy="0.0001627"
        iyz="-5.389E-08"
        izz="0.0001914" />
    </inertial>
    <visual>
      <origin
        xyz="0 0 0"
        rpy="0 0 0" />
      <geometry>
        <mesh
          filename="../meshes/diff1.STL" />
      </geometry>
      <material
        name="">
        <color
          rgba="0.79216 0.81961 0.93333 1" />
      </material>
    </visual>
    <collision>
      <origin
        xyz="0 0 0"
        rpy="0 0 0" />
      <geometry>
        <mesh
          filename="../meshes/diff1.STL" />
      </geometry>
    </collision>
  </link>
  <joint
    name="pitch"
    type="revolute">
    <origin
      xyz="-0.22864 -0.20765 -0.10663"
      rpy="-3.1416 0 -1.75" />
    <parent
      link="link2" />
    <child
      link="diff1" />
    <axis
      xyz="0 0 1" />
    <limit
      lower="-3.14"
      upper="3.14"
      effort="0"
      velocity="0" />
  </joint>
  <link
    name="diff 2">
    <inertial>
      <origin
        xyz="0.10385 -0.0274 0.0432"
        rpy="0 0 0" />
      <mass
        value="0.50646" />
      <inertia
        ixx="0.00053971"
        ixy="-9.4168E-08"
        ixz="5.8369E-05"
        iyy="0.00099608"
        iyz="4.9501E-07"
        izz="0.00066814" />
    </inertial>
    <visual>
      <origin
        xyz="0 0 0"
        rpy="0 0 0" />
      <geometry>
        <mesh
          filename="../meshes/diff 2.STL" />
      </geometry>
      <material
        name="">
        <color
          rgba="0.79216 0.81961 0.93333 1" />
      </material>
    </visual>
    <collision>
      <origin
        xyz="0 0 0"
        rpy="0 0 0" />
      <geometry>
        <mesh
          filename="../meshes/diff 2.STL" />
      </geometry>
    </collision>
  </link>
  <joint
    name="yprroll"
    type="revolute">
    <origin
      xyz="0.019826 0.089558 0.048964"
      rpy="-1.5708 1.25 -0.84529" />
    <parent
      link="diff1" />
    <child
      link="diff 2" />
    <axis
      xyz="0 0 1" />
    <limit
      lower="-3.14"
      upper="3.14"
      effort="0"
      velocity="0" />
  </joint>
  <link
    name="claw">
    <inertial>
      <origin
        xyz="-0.022045 0.00067745 -0.0069498"
        rpy="0 0 0" />
      <mass
        value="0.078604" />
      <inertia
        ixx="1.3877E-05"
        ixy="1.7157E-18"
        ixz="2.238E-06"
        iyy="0.00011054"
        iyz="-1.5416E-19"
        izz="0.00012082" />
    </inertial>
    <visual>
      <origin
        xyz="0 0 0"
        rpy="0 0 0" />
      <geometry>
        <mesh
          filename="../meshes/claw.STL" />
      </geometry>
      <material
        name="">
        <color
          rgba="0.79216 0.81961 0.93333 1" />
      </material>
    </visual>
    <collision>
      <origin
        xyz="0 0 0"
        rpy="0 0 0" />
      <geometry>
        <mesh
          filename="../meshes/claw.STL" />
      </geometry>
    </collision>
  </link>
  <joint
    name="claw"
    type="prismatic">
    <origin
      xyz="0.12531 -0.028177 0.12448"
      rpy="3.1416 -1.5708 0" />
    <parent
      link="diff 2" />
    <child
      link="claw" />
    <axis
      xyz="0 0 1" />
    <limit
      lower="-3.14"
      upper="3.14"
      effort="0"
      velocity="0" />
  </joint>
</robot>