<?xml version="1.0" encoding="utf-8"?>
<!-- This URDF was automatically created by SolidWorks to URDF Exporter! Originally created by Stephen Brawner (brawner@gmail.com) 
     Commit Version: 1.6.0-4-g7f85cfe  Build Version: 1.6.7995.38578
     For more information, please see http://wiki.ros.org/sw_urdf_exporter -->
<robot
  name="ARM YPR GRIPPER_7(2)">
 <link name="worldb"/>
    <joint name="world_joint" type="fixed">
      <parent link="worldb"/>
      <child link="base_link"/>
      <origin xyz="0 0 0" rpy="-1.5708 0 0"/>
    </joint>
  <link
    name="base_link">
    <inertial>
      <origin
        xyz="1.09461925457827 -0.124858087365365 -0.201953049950335"
        rpy="0 0 0" />
      <mass
        value="4.02995163253206" />
      <inertia
        ixx="0.0142526010590084"
        ixy="0.0002672269741825"
        ixz="-0.000921986919945574"
        iyy="0.0120910989509573"
        iyz="0.00166810244583697"
        izz="0.0130919906841085" />
    </inertial>
    <visual>
      <origin
        xyz="0 0 0"
        rpy="0 0 0" />
      <geometry>
        <mesh
          filename="../meshes/base_link.STL" />
      </geometry>
      <material
        name="">
        <color
          rgba="0.792156862745098 0.819607843137255 0.933333333333333 1" />
      </material>
    </visual>
    <collision>
      <origin
        xyz="0 0 0"
        rpy="0 0 0" />
      <geometry>
        <mesh
          filename="../meshes/base_link.STL" />
      </geometry>
    </collision>
  </link>
  <link
    name="turntable">
    <inertial>
      <origin
        xyz="0.110818393872211 -0.00147585336417388 -0.0260116131683339"
        rpy="0 0 0" />
      <mass
        value="2.52870378509004" />
      <inertia
        ixx="0.00641134708621849"
        ixy="0.00085313874640523"
        ixz="-9.62866160909338E-06"
        iyy="0.0048661801238519"
        iyz="2.16956524846366E-05"
        izz="0.00929271252291501" />
    </inertial>
    <visual>
      <origin
        xyz="0 0 0"
        rpy="0 0 0" />
      <geometry>
        <mesh
          filename="../meshes/turntable.STL" />
      </geometry>
      <material
        name="">
        <color
          rgba="0.650980392156863 0.619607843137255 0.588235294117647 1" />
      </material>
    </visual>
    <collision>
      <origin
        xyz="0 0 0"
        rpy="0 0 0" />
      <geometry>
        <mesh
          filename="../meshes/turntable.STL" />
      </geometry>
    </collision>
  </link>
  <joint
    name="turntable_joint"
    type="revolute">
    <origin
      xyz="1.35000046806038 -0.216 -0.311161541452805"
      rpy="1.5707963267949 -1.15332436277035 3.14159265358979" />
    <parent
      link="base_link" />
    <child
      link="turntable" />
    <axis
      xyz="0 0 -1" />
    <limit
      lower="-3.14"
      upper="3.14"
      effort="0"
      velocity="0" />
  </joint>
  <link
    name="worm_pitch">
    <inertial>
      <origin
        xyz="-0.00975815373251407 -0.17702360275832 -0.0436591027878328"
        rpy="0 0 0" />
      <mass
        value="3.22088245145389" />
      <inertia
        ixx="0.0280751971325668"
        ixy="-4.98338642611533E-08"
        ixz="-6.19381508416858E-07"
        iyy="0.00410053168842437"
        iyz="-0.00592538356339953"
        izz="0.0252047377317841" />
    </inertial>
    <visual>
      <origin
        xyz="0 0 0"
        rpy="0 0 0" />
      <geometry>
        <mesh
          filename="../meshes/worm_pitch.STL" />
      </geometry>
      <material
        name="">
        <color
          rgba="0.792156862745098 0.819607843137255 0.933333333333333 1" />
      </material>
    </visual>
    <collision>
      <origin
        xyz="0 0 0"
        rpy="0 0 0" />
      <geometry>
        <mesh
          filename="../meshes/worm_pitch.STL" />
      </geometry>
    </collision>
  </link>
  <joint
    name="pitch1_joint"
    type="revolute">
    <origin
      xyz="0.0735164068372525 0.077745638479509 -0.151720000000009"
      rpy="1.5707963267949 0 0.417471964024542" />
    <parent
      link="turntable" />
    <child
      link="worm_pitch" />
    <axis
      xyz="-1 0 0" />
    <limit
      lower="-3.14"
      upper="3.14"
      effort="0"
      velocity="0" />
  </joint>
  <link
    name="pulley">
    <inertial>
      <origin
        xyz="-0.485530896858826 -0.204504115324753 -0.0419112837236347"
        rpy="0 0 0" />
      <mass
        value="1.78809149742768" />
      <inertia
        ixx="0.00131451399049416"
        ixy="-9.75011012034222E-05"
        ixz="5.43543158749487E-08"
        iyy="0.00304052238726918"
        iyz="-2.95545758988027E-06"
        izz="0.00323857434242465" />
    </inertial>
    <visual>
      <origin
        xyz="0 0 0"
        rpy="0 0 0" />
      <geometry>
        <mesh
          filename="../meshes/pulley.STL" />
      </geometry>
      <material
        name="">
        <color
          rgba="0.898039215686275 0.917647058823529 0.929411764705882 1" />
      </material>
    </visual>
    <collision>
      <origin
        xyz="0 0 0"
        rpy="0 0 0" />
      <geometry>
        <mesh
          filename="../meshes/pulley.STL" />
      </geometry>
    </collision>
  </link>
  <joint
    name="pitch2_joint"
    type="revolute">
    <origin
      xyz="-0.0599999999999885 -0.289979355471976 0.310703996433991"
      rpy="1.5707963267949 -1.37469687411002 -1.5707963267949" />
    <parent
      link="worm_pitch" />
    <child
      link="pulley" />
    <axis
      xyz="0 0 -1" />
    <limit
      lower="-3.14"
      upper="3.14"
      effort="0"
      velocity="0" />
  </joint>
  <link
    name="pitch">
    <inertial>
      <origin
        xyz="0.062109301197713 0.490258285211261 -0.343882455697338"
        rpy="0 0 0" />
      <mass
        value="0.925309312313834" />
      <inertia
        ixx="0.000905421678530425"
        ixy="-4.55994715354063E-05"
        ixz="-0.000136324904651109"
        iyy="0.00102354139371751"
        iyz="0.000198583707800764"
        izz="0.00105408983968959" />
    </inertial>
    <visual>
      <origin
        xyz="0 0 0"
        rpy="0 0 0" />
      <geometry>
        <mesh
          filename="../meshes/pitch.STL" />
      </geometry>
      <material
        name="">
        <color
          rgba="0.792156862745098 0.819607843137255 0.933333333333333 1" />
      </material>
    </visual>
    <collision>
      <origin
        xyz="0 0 0"
        rpy="0 0 0" />
      <geometry>
        <mesh
          filename="../meshes/pitch.STL" />
      </geometry>
    </collision>
  </link>
  <joint
    name="ypr_pitch_joint"
    type="revolute">
    <origin
      xyz="-0.19051 -0.17768 -0.112"
      rpy="0.90468 -1.5708 0" />
    <parent
      link="pulley" />
    <child
      link="pitch" />
    <axis
      xyz="-1 0 0" />
    <limit
      lower="-3.14"
      upper="3.14"
      effort="0"
      velocity="0" />
  </joint>
  <link
    name="roll">
    <inertial>
      <origin
        xyz="-0.307367580888456 -0.166443734492417 -0.427585276240788"
        rpy="0 0 0" />
      <mass
        value="0.82217415730679" />
      <inertia
        ixx="0.00081903497839913"
        ixy="0.000154963541215627"
        ixz="-0.000144149317152014"
        iyy="0.0009277911906097"
        iyz="-0.00012325641290026"
        izz="0.000939233305226669" />
    </inertial>
    <visual>
      <origin
        xyz="0 0 0"
        rpy="0 0 0" />
      <geometry>
        <mesh
          filename="../meshes/roll.STL" />
      </geometry>
      <material
        name="">
        <color
          rgba="0.792156862745098 0.819607843137255 0.933333333333333 1" />
      </material>
    </visual>
    <collision>
      <origin
        xyz="0 0 0"
        rpy="0 0 0" />
      <geometry>
        <mesh
          filename="../meshes/roll.STL" />
      </geometry>
    </collision>
  </link>
  <joint
    name="roll"
    type="continuous">
    <origin
      xyz="0.05225 0.069756 0"
      rpy="1.5708 -1.1062 0" />
    <parent
      link="pitch" />
    <child
      link="roll" />
    <axis
      xyz="-0.57847 -0.28989 -0.76245" />
    <limit
      lower="-3.14"
      upper="3.14"
      effort="0"
      velocity="0" />
  </joint>
</robot>