<?xml version="1.0" encoding="utf-8"?>
<!-- This URDF was automatically created by SolidWorks to URDF Exporter! Originally created by Stephen Brawner (brawner@gmail.com) 
     Commit Version: 1.6.0-4-g7f85cfe  Build Version: 1.6.7995.38578
     For more information, please see http://wiki.ros.org/sw_urdf_exporter -->
<robot
  name="ARM YPR GRIPPER_7">
<link name="worldb"/>
    
    <joint name="world_joint" type="fixed">
      <parent link="worldb"/>
      <child link="base_link"/>
      <origin xyz="0 0 0" rpy="-1.5708 0 0"/>
    </joint>

  <link
    name="base_link">
    <inertial>
      <origin
        xyz="1.12169088699127 -0.121140693558929 -0.213529355221054"
        rpy="0 0 0" />
      <mass
        value="4.50779680589233" />
      <inertia
        ixx="0.0155744669511241"
        ixy="0.000267312829592054"
        ixz="-0.000921990975110573"
        iyy="0.0123110151558508"
        iyz="0.00166823235851846"
        izz="0.0144138530523192" />
    </inertial>
    <visual>
      <origin
        xyz="0 0 0"
        rpy="0 0 0" />
      <geometry>
        <mesh
          filename="package://ARM YPR GRIPPER_7/meshes/base_link.STL" />
      </geometry>
      <material
        name="">
        <color
          rgba="0.792156862745098 0.819607843137255 0.933333333333333 1" />
      </material>
    </visual>
    <collision>
      <origin
        xyz="0 0 0"
        rpy="0 0 0" />
      <geometry>
        <mesh
          filename="../meshes/base_link.STL" />
      </geometry>
    </collision>
  </link>
  <link
    name="turntable">
    <inertial>
      <origin
        xyz="0.105763980678447 -0.00089189198876527 -0.0260116131683339"
        rpy="0 0 0" />
      <mass
        value="2.52870378509003" />
      <inertia
        ixx="0.00641134887101375"
        ixy="0.000853146367351283"
        ixz="-9.61006870504373E-06"
        iyy="0.00486617833905661"
        iyz="2.16935043543991E-05"
        izz="0.00929271252291498" />
    </inertial>
    <visual>
      <origin
        xyz="0 0 0"
        rpy="0 0 0" />
      <geometry>
        <mesh
          filename="package://ARM YPR GRIPPER_7/meshes/turntable.STL" />
      </geometry>
      <material
        name="">
        <color
          rgba="0.650980392156863 0.619607843137255 0.588235294117647 1" />
      </material>
    </visual>
    <collision>
      <origin
        xyz="0 0 0"
        rpy="0 0 0" />
      <geometry>
        <mesh
          filename="../meshes/turntable.STL" />
      </geometry>
    </collision>
  </link>
  <joint
    name="turntable_joint"
    type="revolute">
    <origin
      xyz="1.35000046806038 -0.216 -0.311161541452805"
      rpy="1.5707963267949 -1.15332436277035 3.14159265358979" />
    <parent
      link="base_link" />
    <child
      link="turntable" />
    <axis
      xyz="0 0 -1" />
    <limit
      lower="-6.28"
      upper="6.28"
      effort="0"
      velocity="0" />
  </joint>
  <link
    name="worm_pitch">
    <inertial>
      <origin
        xyz="-0.00975815373258329 -0.119432998209141 0.138678111763514"
        rpy="0 0 0" />
      <mass
        value="3.22088245146173" />
      <inertia
        ixx="0.0280751971325729"
        ixy="-3.59522261295656E-08"
        ixz="-5.70039309070443E-07"
        iyy="0.0158829956773457"
        iyz="0.0120530236922504"
        izz="0.0134222737428643" />
    </inertial>
    <visual>
      <origin
        xyz="0 0 0"
        rpy="0 0 0" />
      <geometry>
        <mesh
          filename="../meshes/worm_pitch.STL" />
      </geometry>
      <material
        name="">
        <color
          rgba="0.792156862745098 0.819607843137255 0.933333333333333 1" />
      </material>
    </visual>
    <collision>
      <origin
        xyz="0 0 0"
        rpy="0 0 0" />
      <geometry>
        <mesh
          filename="../meshes/worm_pitch.STL" />
      </geometry>
    </collision>
  </link>
  <joint
    name="pitch1_joint"
    type="revolute">
    <origin
      xyz="0.0735164068372525 0.077745638479509 -0.151720000000009"
      rpy="1.5707963267949 0 0.417471964024542" />
    <parent
      link="turntable" />
    <child
      link="worm_pitch" />
    <axis
      xyz="-1 0 0" />
    <limit
      lower="-3.14"
      upper="3.14"
      effort="0"
      velocity="0" />
  </joint>
  <link
    name="pulley">
    <inertial>
      <origin
        xyz="-0.067342566624464 -0.0631791995553346 -0.0419109788002336"
        rpy="0 0 0" />
      <mass
        value="1.78809248147294" />
      <inertia
        ixx="0.00213333923198405"
        ixy="-0.000867369411845703"
        ixz="1.95378069418704E-06"
        iyy="0.0022216968306464"
        iyz="-2.218237233129E-06"
        izz="0.00323857402349486" />
    </inertial>
    <visual>
      <origin
        xyz="0 0 0"
        rpy="0 0 0" />
      <geometry>
        <mesh
          filename="../meshes/pulley.STL" />
      </geometry>
      <material
        name="">
        <color
          rgba="0.898039215686275 0.917647058823529 0.929411764705882 1" />
      </material>
    </visual>
    <collision>
      <origin
        xyz="0 0 0"
        rpy="0 0 0" />
      <geometry>
        <mesh
          filename="../meshes/pulley.STL" />
      </geometry>
    </collision>
  </link>
  <joint
    name="pitch2_joint"
    type="revolute">
    <origin
      xyz="-0.06 -0.28998 0.3107"
      rpy="1.5708 -1.3747 -1.5708" />
    <parent
      link="worm_pitch" />
    <child
      link="pulley" />
    <axis
      xyz="0 0 -1" />
    <limit
      lower="-3.14"
      upper="3.14"
      effort="0"
      velocity="0" />
  </joint>
  <link
    name="pitch">
    <inertial>
      <origin
        xyz="0.0621093053463832 0.134911342325096 0.00321851094996328"
        rpy="0 0 0" />
      <mass
        value="0.925309423783586" />
      <inertia
        ixx="0.000905421686824765"
        ixy="5.34409864880228E-05"
        ixz="-0.000133446110442722"
        iyy="0.000840392256623591"
        iyz="1.72313152784089E-05"
        izz="0.00123723911311522" />
    </inertial>
    <visual>
      <origin
        xyz="0 0 0"
        rpy="0 0 0" />
      <geometry>
        <mesh
          filename="../meshes/pitch.STL" />
      </geometry>
      <material
        name="">
        <color
          rgba="0.792156862745098 0.819607843137255 0.933333333333333 1" />
      </material>
    </visual>
    <collision>
      <origin
        xyz="0 0 0"
        rpy="0 0 0" />
      <geometry>
        <mesh
          filename="../meshes/pitch.STL" />
      </geometry>
    </collision>
  </link>
  <joint
    name="ypr_pitch_joint"
    type="revolute">
    <origin
      xyz="-0.19051 -0.17768 -0.112"
      rpy="0.90468 -1.5708 0" />
    <parent
      link="pulley" />
    <child
      link="pitch" />
    <axis
      xyz="-1 0 0" />
    <limit
      lower="-3.14"
      upper="3.14"
      effort="0"
      velocity="0" />
  </joint>
  <link
    name="roll">
    <inertial>
      <origin
        xyz="0.00820967914203474 -0.00829727339334974 -0.0741025510125426"
        rpy="0 0 0" />
      <mass
        value="0.822174268776543" />
      <inertia
        ixx="0.000957891470934724"
        ixy="0.000221680605326053"
        ixz="-3.9340990708054E-05"
        iyy="0.000959787814957132"
        iyz="4.00432863294902E-05"
        izz="0.000768380332969696" />
    </inertial>
    <visual>
      <origin
        xyz="0 0 0"
        rpy="0 0 0" />
      <geometry>
        <mesh
          filename="../meshes/roll.STL" />
      </geometry>
      <material
        name="">
        <color
          rgba="0.792156862745098 0.819607843137255 0.933333333333333 1" />
      </material>
    </visual>
    <collision>
      <origin
        xyz="0 0 0"
        rpy="0 0 0" />
      <geometry>
        <mesh
          filename="../meshes/roll.STL" />
      </geometry>
    </collision>
  </link>
  <joint
    name="roll"
    type="continuous">
    <origin
      xyz="0.05225 0.069756 0"
      rpy="1.5708 -1.1062 0" />
    <parent
      link="pitch" />
    <child
      link="roll" />
    <axis
      xyz="0 0 -1" />
    <limit
      lower="-3.14"
      upper="3.14"
      effort="0"
      velocity="0" />
  </joint>
  <link
    name="grip">
    <inertial>
      <origin
        xyz="-0.0264212696817925 6.99440505513849E-15 0.0519403659924383"
        rpy="0 0 0" />
      <mass
        value="0.134543517946272" />
      <inertia
        ixx="5.22930570804675E-05"
        ixy="1.78215732102305E-18"
        ixz="-2.24360153272595E-06"
        iyy="0.000148952960809367"
        iyz="5.42101086242752E-20"
        izz="0.000126256855074672" />
    </inertial>
    <visual>
      <origin
        xyz="0 0 0"
        rpy="0 0 0" />
      <geometry>
        <mesh
          filename="../meshes/grip.STL" />
      </geometry>
      <material
        name="">
        <color
          rgba="0.792156862745098 0.819607843137255 0.933333333333333 1" />
      </material>
    </visual>
    <collision>
      <origin
        xyz="0 0 0"
        rpy="0 0 0" />
      <geometry>
        <mesh
          filename="../meshes/grip.STL" />
      </geometry>
    </collision>
  </link>
  <joint
    name="grip"
    type="prismatic">
    <origin
      xyz="0.086479 -0.086479 -0.11021"
      rpy="2.3562 -1.5708 0" />
    <parent
      link="roll" />
    <child
      link="grip" />
    <axis
      xyz="0 0 -1" />
    <limit
      lower="-3.14"
      upper="3.14"
      effort="0"
      velocity="0" />
  </joint>
</robot>