<?xml version="1.0" encoding="utf-8"?>
<!-- This URDF was automatically created by SolidWorks to URDF Exporter! Originally created by Stephen Brawner (brawner@gmail.com) 
     Commit Version: 1.6.0-4-g7f85cfe  Build Version: 1.6.7995.38578
     For more information, please see http://wiki.ros.org/sw_urdf_exporter -->
<robot
  name="ARM YPR GRIPPER_7(3)">
 <link name="worldb"/>
    <joint name="world_joint" type="fixed">
      <parent link="worldb"/>
      <child link="base_link"/>
      <origin xyz="0 0 0" rpy="-1.5708 0 0"/>
    </joint>
  <link
    name="base_link">
    <inertial>
      <origin
        xyz="1.09427024557404 -0.202481216910072 0.125135264568647"
        rpy="0 0 0" />
      <mass
        value="4.02995163253206" />
      <inertia
        ixx="0.0142526010590084"
        ixy="-0.000921986919945574"
        ixz="-0.0002672269741825"
        iyy="0.0130919906841085"
        iyz="-0.00166810244583697"
        izz="0.0120910989509573" />
    </inertial>
    <visual>
      <origin
        xyz="0 0 0"
        rpy="0 0 0" />
      <geometry>
        <mesh
          filename="../meshes/base_link.STL" />
      </geometry>
      <material
        name="">
        <color
          rgba="0.792156862745098 0.819607843137255 0.933333333333333 1" />
      </material>
    </visual>
    <collision>
      <origin
        xyz="0 0 0"
        rpy="0 0 0" />
      <geometry>
        <mesh
          filename="../meshes/base_link.STL" />
      </geometry>
    </collision>
  </link>
  <link
    name="turntable">
    <inertial>
      <origin
        xyz="-0.00166977411269786 0.000326905921522735 -0.234011613168333"
        rpy="0 0 0" />
      <mass
        value="2.52870378509004" />
      <inertia
        ixx="0.00487001876046124"
        ixy="-0.000856577593722426"
        ixz="-2.16626157193247E-05"
        iyy="0.00640750844960913"
        iyz="-9.66775820890341E-06"
        izz="0.009292712522915" />
    </inertial>
    <visual>
      <origin
        xyz="0 0 0"
        rpy="0 0 0" />
      <geometry>
        <mesh
          filename="../meshes/turntable.STL" />
      </geometry>
      <material
        name="">
        <color
          rgba="0.650980392156863 0.619607843137255 0.588235294117647 1" />
      </material>
    </visual>
    <collision>
      <origin
        xyz="0 0 0"
        rpy="0 0 0" />
      <geometry>
        <mesh
          filename="../meshes/turntable.STL" />
      </geometry>
    </collision>
  </link>
  <joint
    name="turntable_joint"
    type="continuous">
    <origin
      xyz="1.3062 -0.008 -0.21244"
      rpy="1.5708 0.4197 -3.1416" />
    <parent
      link="base_link" />
    <child
      link="turntable" />
    <axis
      xyz="0 0 -1" />
    <limit
      lower="0"
      upper="0"
      effort="0"
      velocity="0" />
  </joint>
  <link
    name="worm_pitch">
    <inertial>
      <origin
        xyz="-0.00975815373260705 -0.122290051681618 0.136123713907067"
        rpy="0 0 0" />
      <mass
        value="3.22088245146418" />
      <inertia
        ixx="0.028075197132574"
        ixy="-3.66959106019684E-08"
        ixz="-5.7074798108831E-07"
        iyy="0.0153806055256586"
        iyz="0.0120933072327016"
        izz="0.0139246638945512" />
    </inertial>
    <visual>
      <origin
        xyz="0 0 0"
        rpy="0 0 0" />
      <geometry>
        <mesh
          filename="../meshes/worm_pitch.STL" />
      </geometry>
      <material
        name="">
        <color
          rgba="0.792156862745098 0.819607843137255 0.933333333333333 1" />
      </material>
    </visual>
    <collision>
      <origin
        xyz="0 0 0"
        rpy="0 0 0" />
      <geometry>
        <mesh
          filename="../meshes/worm_pitch.STL" />
      </geometry>
    </collision>
  </link>
  <joint
    name="pitch1_joint"
    type="revolute">
    <origin
      xyz="-0.077669 -0.034657 -0.35972"
      rpy="1.5708 0 1.9905" />
    <parent
      link="turntable" />
    <child
      link="worm_pitch" />
    <axis
      xyz="0 0 0" />
    <limit
      lower="0"
      upper="0"
      effort="0"
      velocity="0" />
  </joint>
  <link
    name="pulley">
    <inertial>
      <origin
        xyz="-0.0673426015925775 -0.0631792213547742 -0.0419110050060416"
        rpy="0 0 0" />
      <mass
        value="1.78809301817132" />
      <inertia
        ixx="0.00213333962795825"
        ixy="-0.000867369380655108"
        ixz="1.95378138236375E-06"
        iyy="0.00222169684621381"
        iyz="-2.21824277051348E-06"
        izz="0.00323857443296241" />
    </inertial>
    <visual>
      <origin
        xyz="0 0 0"
        rpy="0 0 0" />
      <geometry>
        <mesh
          filename="../meshes/pulley.STL" />
      </geometry>
      <material
        name="">
        <color
          rgba="0.898039215686275 0.917647058823529 0.929411764705882 1" />
      </material>
    </visual>
    <collision>
      <origin
        xyz="0 0 0"
        rpy="0 0 0" />
      <geometry>
        <mesh
          filename="../meshes/pulley.STL" />
      </geometry>
    </collision>
  </link>
  <joint
    name="pitch2_joint"
    type="revolute">
    <origin
      xyz="-0.06 -0.29638 0.3046"
      rpy="1.5708 -1.3527 -1.5708" />
    <parent
      link="worm_pitch" />
    <child
      link="pulley" />
    <axis
      xyz="0 0 0" />
    <limit
      lower="0"
      upper="0"
      effort="0"
      velocity="0" />
  </joint>
  <link
    name="pitch">
    <inertial>
      <origin
        xyz="0.0621093052792882 0.134911339866618 0.00321850945902857"
        rpy="0 0 0" />
      <mass
        value="0.925309237354222" />
      <inertia
        ixx="0.000905421667853945"
        ixy="5.34410521521279E-05"
        ixz="-0.000133446093158407"
        iyy="0.000840392018840474"
        iyz="1.72313345234428E-05"
        izz="0.00123723886418401" />
    </inertial>
    <visual>
      <origin
        xyz="0 0 0"
        rpy="0 0 0" />
      <geometry>
        <mesh
          filename="../meshes/pitch.STL" />
      </geometry>
      <material
        name="">
        <color
          rgba="0.792156862745098 0.819607843137255 0.933333333333333 1" />
      </material>
    </visual>
    <collision>
      <origin
        xyz="0 0 0"
        rpy="0 0 0" />
      <geometry>
        <mesh
          filename="../meshes/pitch.STL" />
      </geometry>
    </collision>
  </link>
  <joint
    name="ypr_pitch_joint"
    type="revolute">
    <origin
      xyz="-0.19051 -0.17768 -0.112"
      rpy="0.90468 -1.5708 0" />
    <parent
      link="pulley" />
    <child
      link="pitch" />
    <axis
      xyz="0 0 0" />
    <limit
      lower="0"
      upper="0"
      effort="0"
      velocity="0" />
  </joint>
  <link
    name="roll">
    <inertial>
      <origin
        xyz="0.00820967776761528 -0.00829727431426236 -0.074102550252656"
        rpy="0 0 0" />
      <mass
        value="0.82217408126112" />
      <inertia
        ixx="0.00095789128315225"
        ixy="0.000221680503309467"
        ixz="-3.93410375747593E-05"
        iyy="0.00095978773652777"
        iyz="4.00433372780917E-05"
        izz="0.000768380095989253" />
    </inertial>
    <visual>
      <origin
        xyz="0 0 0"
        rpy="0 0 0" />
      <geometry>
        <mesh
          filename="../meshes/roll.STL" />
      </geometry>
      <material
        name="">
        <color
          rgba="0.792156862745098 0.819607843137255 0.933333333333333 1" />
      </material>
    </visual>
    <collision>
      <origin
        xyz="0 0 0"
        rpy="0 0 0" />
      <geometry>
        <mesh
          filename="../meshes/roll.STL" />
      </geometry>
    </collision>
  </link>
  <joint
    name="roll"
    type="continuous">
    <origin
      xyz="0.05225 0.069756 0"
      rpy="1.5708 -1.1062 0" />
    <parent
      link="pitch" />
    <child
      link="roll" />
    <axis
      xyz="0 0 0" />
    <limit
      lower="0"
      upper="0"
      effort="0"
      velocity="0" />
  </joint>
  <link
    name="grip">
    <inertial>
      <origin
        xyz="-0.0253848183695893 0.000677446241029944 -0.00279078982371761"
        rpy="0 0 0" />
      <mass
        value="0.0848713844080814" />
      <inertia
        ixx="2.7994810224387E-05"
        ixy="-5.42948119190007E-19"
        ixz="2.23797026426176E-06"
        iyy="0.000124654921884766"
        iyz="0"
        izz="0.000120801849157496" />
    </inertial>
    <visual>
      <origin
        xyz="0 0 0"
        rpy="0 0 0" />
      <geometry>
        <mesh
          filename="../meshes/grip.STL" />
      </geometry>
      <material
        name="">
        <color
          rgba="0.792156862745098 0.819607843137255 0.933333333333333 1" />
      </material>
    </visual>
    <collision>
      <origin
        xyz="0 0 0"
        rpy="0 0 0" />
      <geometry>
        <mesh
          filename="../meshes/grip.STL" />
      </geometry>
    </collision>
  </link>
  <joint
    name="grip"
    type="fixed">
    <origin
      xyz="0.026864 -0.025906 -0.17748"
      rpy="2.3562 1.5708 0" />
    <parent
      link="roll" />
    <child
      link="grip" />
    <axis
      xyz="0 0 0" />
  </joint>
</robot>